Workbook

Sheet Legend
A1: Accreditation Export — how to read this file
A2: Sample Engineering College · Academic year 2025-26 · Generated by Velaivaaipu
A5: Topic | B5: Guidance
A6: Summary | B6: Department-wise graduating strength, placement and progression metrics.
A7: Placement Register | B7: One row per graduating student, placed or not.
A8: Progression | B8: Higher studies and competitive examination records.
A9: Employer Summary | B9: Recruiting companies, offers and package range.
A10: DVV Evidence Log | B10: Every claim with evidence status; work missing evidence to zero.
A11: Framework caveat | B11: NAAC metric numbering is in transition. This export supplies stable underlying placement data; map it to the current SSR, AQAR, SAR or AICTE template.
A12: Evidence | B12: A placement or progression claim without supporting evidence should not be counted.
A13: Median package | B13: Calculated by the platform; regenerate after changing register data.

Sheet Summary
A1: Student Progression and Placement — Summary
A2: Sample Engineering College · Academic year 2025-26 · Live formulas over the register sheets
A5: Department | B5: Graduated | C5: Placed | D5: Placement % | E5: Higher Studies | F5: Qualified Exams | G5: Total Progression | H5: Progression % | I5: Average Package (Rs. LPA) | J5: Highest Package (Rs. LPA) | K5: Median Package (Rs. LPA)
A6: CSE | B6: =COUNTIF('Placement Register'!$G$6:$G$145,A6) -> 38 | C6: =COUNTIFS('Placement Register'!$G$6:$G$145,A6,'Placement Register'!$I$6:$I$145,"Placed") -> 22 | D6: =IFERROR(C6/B6,0) -> 0.57894737 | E6: =COUNTIFS(Progression!$F$6:$F$25,A6,Progression!$G$6:$G$25,"Higher Studies") -> 3 | F6: =COUNTIFS(Progression!$F$6:$F$25,A6,Progression!$G$6:$G$25,"Qualified Competitive Exam") -> 3 | G6: =C6+E6+F6 -> 28 | H6: =IFERROR(G6/B6,0) -> 0.73684211 | I6: =IFERROR(AVERAGEIFS('Placement Register'!$M$6:$M$145,'Placement Register'!$G$6:$G$145,A6,'Placement Register'!$I$6:$I$145,"Placed"),0) -> 4.81 | J6: =IFERROR(MAXIFS('Placement Register'!$M$6:$M$145,'Placement Register'!$G$6:$G$145,A6,'Placement Register'!$I$6:$I$145,"Placed"),0) -> 7.2 | K6: 4.8
A7: ECE | B7: =COUNTIF('Placement Register'!$G$6:$G$145,A7) -> 30 | C7: =COUNTIFS('Placement Register'!$G$6:$G$145,A7,'Placement Register'!$I$6:$I$145,"Placed") -> 23 | D7: =IFERROR(C7/B7,0) -> 0.76666667 | E7: =COUNTIFS(Progression!$F$6:$F$25,A7,Progression!$G$6:$G$25,"Higher Studies") -> 1 | F7: =COUNTIFS(Progression!$F$6:$F$25,A7,Progression!$G$6:$G$25,"Qualified Competitive Exam") -> 2 | G7: =C7+E7+F7 -> 26 | H7: =IFERROR(G7/B7,0) -> 0.86666667 | I7: =IFERROR(AVERAGEIFS('Placement Register'!$M$6:$M$145,'Placement Register'!$G$6:$G$145,A7,'Placement Register'!$I$6:$I$145,"Placed"),0) -> 5.4904348 | J7: =IFERROR(MAXIFS('Placement Register'!$M$6:$M$145,'Placement Register'!$G$6:$G$145,A7,'Placement Register'!$I$6:$I$145,"Placed"),0) -> 8.22 | K7: 5.34
A8: EEE | B8: =COUNTIF('Placement Register'!$G$6:$G$145,A8) -> 22 | C8: =COUNTIFS('Placement Register'!$G$6:$G$145,A8,'Placement Register'!$I$6:$I$145,"Placed") -> 16 | D8: =IFERROR(C8/B8,0) -> 0.72727273 | E8: =COUNTIFS(Progression!$F$6:$F$25,A8,Progression!$G$6:$G$25,"Higher Studies") -> 2 | F8: =COUNTIFS(Progression!$F$6:$F$25,A8,Progression!$G$6:$G$25,"Qualified Competitive Exam") -> 1 | G8: =C8+E8+F8 -> 19 | H8: =IFERROR(G8/B8,0) -> 0.86363636 | I8: =IFERROR(AVERAGEIFS('Placement Register'!$M$6:$M$145,'Placement Register'!$G$6:$G$145,A8,'Placement Register'!$I$6:$I$145,"Placed"),0) -> 4.955625 | J8: =IFERROR(MAXIFS('Placement Register'!$M$6:$M$145,'Placement Register'!$G$6:$G$145,A8,'Placement Register'!$I$6:$I$145,"Placed"),0) -> 7.29 | K8: 4.45
A9: IT | B9: =COUNTIF('Placement Register'!$G$6:$G$145,A9) -> 26 | C9: =COUNTIFS('Placement Register'!$G$6:$G$145,A9,'Placement Register'!$I$6:$I$145,"Placed") -> 16 | D9: =IFERROR(C9/B9,0) -> 0.61538462 | E9: =COUNTIFS(Progression!$F$6:$F$25,A9,Progression!$G$6:$G$25,"Higher Studies") -> 2 | F9: =COUNTIFS(Progression!$F$6:$F$25,A9,Progression!$G$6:$G$25,"Qualified Competitive Exam") -> 2 | G9: =C9+E9+F9 -> 20 | H9: =IFERROR(G9/B9,0) -> 0.76923077 | I9: =IFERROR(AVERAGEIFS('Placement Register'!$M$6:$M$145,'Placement Register'!$G$6:$G$145,A9,'Placement Register'!$I$6:$I$145,"Placed"),0) -> 5.366875 | J9: =IFERROR(MAXIFS('Placement Register'!$M$6:$M$145,'Placement Register'!$G$6:$G$145,A9,'Placement Register'!$I$6:$I$145,"Placed"),0) -> 7.3 | K9: 5.38
A10: MECH | B10: =COUNTIF('Placement Register'!$G$6:$G$145,A10) -> 24 | C10: =COUNTIFS('Placement Register'!$G$6:$G$145,A10,'Placement Register'!$I$6:$I$145,"Placed") -> 17 | D10: =IFERROR(C10/B10,0) -> 0.70833333 | E10: =COUNTIFS(Progression!$F$6:$F$25,A10,Progression!$G$6:$G$25,"Higher Studies") -> 3 | F10: =COUNTIFS(Progression!$F$6:$F$25,A10,Progression!$G$6:$G$25,"Qualified Competitive Exam") -> 1 | G10: =C10+E10+F10 -> 21 | H10: =IFERROR(G10/B10,0) -> 0.875 | I10: =IFERROR(AVERAGEIFS('Placement Register'!$M$6:$M$145,'Placement Register'!$G$6:$G$145,A10,'Placement Register'!$I$6:$I$145,"Placed"),0) -> 5.3064706 | J10: =IFERROR(MAXIFS('Placement Register'!$M$6:$M$145,'Placement Register'!$G$6:$G$145,A10,'Placement Register'!$I$6:$I$145,"Placed"),0) -> 7.52 | K10: 5.18
A11: INSTITUTION TOTAL | B11: =SUM(B6:B10) -> 140 | C11: =SUM(C6:C10) -> 94 | D11: =IFERROR(C11/B11,0) -> 0.67142857 | E11: =SUM(E6:E10) -> 11 | F11: =SUM(F6:F10) -> 9 | G11: =SUM(G6:G10) -> 114 | H11: =IFERROR(G11/B11,0) -> 0.81428571 | I11: =IFERROR(AVERAGEIF('Placement Register'!$I$6:$I$145,"Placed",'Placement Register'!$M$6:$M$145),0) -> 5.1858511 | J11: =IFERROR(MAXIFS('Placement Register'!$M$6:$M$145,'Placement Register'!$I$6:$I$145,"Placed"),0) -> 8.22 | K11: 5.11

Sheet Placement Register
A1: Placement Register
A2: Sample Engineering College · Academic year 2025-26 · One row per graduating student
A5: Sl. No. | B5: Academic Year | C5: Register Number | D5: Name of the Student | E5: Gender | F5: Programme Graduated From | G5: Department | H5: Year of Passing | I5: Outcome | J5: Name of the Employer | K5: Employer Location | L5: Designation / Role | M5: Package (Rs. lakh per annum) | N5: Date of Offer | O5: Source of Offer | P5: Drive / Requisition Reference | Q5: Offer Letter on Record | R5: Verified By | S5: Verified On
A6: 1 | B6: 2025-26 | C6: 96021CS001 | D6: Gokul M | E6: Male | F6: B.E. Computer Science and Engineering | G6: CSE | H6: 2026 | I6: Higher Studies
A7: 2 | B7: 2025-26 | C7: 93721CS002 | D7: Meena G | E7: Female | F7: B.E. Computer Science and Engineering | G7: CSE | H7: 2026 | I7: Placed | J7: Tata Elxsi | K7: Chennai | L7: Software Engineer | M7: 5.38 | N7: 2026-05-14 | O7: Campus drive via Velai Vaaippu | P7: DRV-2026-037 | Q7: Open evidence | R7: TPO Office | S7: 2026-07-08
A8: 3 | B8: 2025-26 | C8: 98321CS003 | D8: Sandhya R | E8: Male | F8: B.E. Computer Science and Engineering | G8: CSE | H8: 2026 | I8: Placed | J8: HCLTech | K8: Chennai | L8: Software Engineer | M8: 4.51 | N8: 2026-02-10 | O8: Pool campus drive | P8: DRV-2026-010 | Q8: Open evidence | R8: TPO Office | S8: 2026-07-19
A9: 4 | B9: 2025-26 | C9: 99721CS004 | D9: Anitha G | E9: Male | F9: B.E. Computer Science and Engineering | G9: CSE | H9: 2026 | I9: Placed | J9: Ashok Leyland | K9: Hosur | L9: Software Engineer | M9: 5.3 | N9: 2026-01-19 | O9: Campus drive via Velai Vaaippu | P9: DRV-2026-040 | Q9: Open evidence | R9: TPO Office | S9: 2026-07-22
A10: 5 | B10: 2025-26 | C10: 95021CS005 | D10: Kalaiselvi T | E10: Female | F10: B.E. Computer Science and Engineering | G10: CSE | H10: 2026 | I10: Placed | J10: Ashok Leyland | K10: Hosur | L10: Systems Engineer | M10: 4.7 | N10: 2026-02-23 | O10: Campus drive via Velai Vaaippu | P10: DRV-2026-006 | Q10: Open evidence | R10: TPO Office | S10: 2026-07-17
A11: 6 | B11: 2025-26 | C11: 96721CS006 | D11: Abinaya V | E11: Male | F11: B.E. Computer Science and Engineering | G11: CSE | H11: 2026 | I11: Placed | J11: TCS | K11: Chennai | L11: Design Engineer | M11: 3.84 | N11: 2026-03-05 | O11: Pool campus drive | P11: DRV-2026-027 | R11: TPO Office | S11: 2026-07-22
A12: 7 | B12: 2025-26 | C12: 98321CS007 | D12: Naveen G | E12: Female | F12: B.E. Computer Science and Engineering | G12: CSE | H12: 2026 | I12: Qualified Competitive Exam
A13: 8 | B13: 2025-26 | C13: 98421CS008 | D13: Sriram N | E13: Male | F13: B.E. Computer Science and Engineering | G13: CSE | H13: 2026 | I13: Not Placed
A14: 9 | B14: 2025-26 | C14: 97021CS009 | D14: Priya P | E14: Male | F14: B.E. Computer Science and Engineering | G14: CSE | H14: 2026 | I14: Higher Studies
A15: 10 | B15: 2025-26 | C15: 95921CS010 | D15: Sathish P | E15: Female | F15: B.E. Computer Science and Engineering | G15: CSE | H15: 2026 | I15: Not Placed
A16: 11 | B16: 2025-26 | C16: 95521CS011 | D16: Divya N | E16: Male | F16: B.E. Computer Science and Engineering | G16: CSE | H16: 2026 | I16: Placed | J16: Freshworks | K16: Chennai | L16: Software Engineer | M16: 6.84 | N16: 2026-03-05 | O16: Campus drive via Velai Vaaippu | P16: DRV-2026-026 | Q16: Open evidence | R16: TPO Office | S16: 2026-07-28
A17: 12 | B17: 2025-26 | C17: 93121CS012 | D17: Abinaya S | E17: Female | F17: B.E. Computer Science and Engineering | G17: CSE | H17: 2026 | I17: Placed | J17: Infosys | K17: Bengaluru | L17: Associate Developer | M17: 5.33 | N17: 2026-03-23 | O17: Pool campus drive | P17: DRV-2026-023 | Q17: Open evidence | R17: TPO Office | S17: 2026-07-13
A18: 13 | B18: 2025-26 | C18: 92021CS013 | D18: Prakash M | E18: Male | F18: B.E. Computer Science and Engineering | G18: CSE | H18: 2026 | I18: Placed | J18: Wipro | K18: Bengaluru | L18: Graduate Engineer Trainee | M18: 3.32 | N18: 2026-05-06 | O18: Off-campus, verified | P18: DRV-2026-019 | R18: TPO Office | S18: 2026-07-14
A19: 14 | B19: 2025-26 | C19: 98821CS014 | D19: Kalaiselvi V | E19: Male | F19: B.E. Computer Science and Engineering | G19: CSE | H19: 2026 | I19: Placed | J19: Sify Technologies | K19: Chennai | L19: Design Engineer | M19: 4.8 | N19: 2026-06-22 | O19: Campus drive via Velai Vaaippu | P19: DRV-2026-030 | Q19: Open evidence | R19: TPO Office | S19: 2026-07-25
A20: 15 | B20: 2025-26 | C20: 96021CS015 | D20: Muthu T | E20: Male | F20: B.E. Computer Science and Engineering | G20: CSE | H20: 2026 | I20: Placed | J20: Freshworks | K20: Chennai | L20: Test Engineer | M20: 7.2 | N20: 2026-02-03 | O20: Campus drive via Velai Vaaippu | P20: DRV-2026-029 | Q20: Open evidence | R20: TPO Office | S20: 2026-07-11
A21: 16 | B21: 2025-26 | C21: 92321CS016 | D21: Sriram R | E21: Male | F21: B.E. Computer Science and Engineering | G21: CSE | H21: 2026 | I21: Placed | J21: Hexaware | K21: Chennai | L21: Software Engineer | M21: 5.1 | N21: 2026-05-01 | O21: Campus drive via Velai Vaaippu | P21: DRV-2026-014 | Q21: Open evidence | R21: TPO Office | S21: 2026-07-05
A22: 17 | B22: 2025-26 | C22: 98721CS017 | D22: Suresh V | E22: Male | F22: B.E. Computer Science and Engineering | G22: CSE | H22: 2026 | I22: Placed | J22: TCS | K22: Chennai | L22: Associate Developer | M22: 4.99 | N22: 2026-04-16 | O22: Pool campus drive | P22: DRV-2026-020 | R22: TPO Office | S22: 2026-07-04
A23: 18 | B23: 2025-26 | C23: 97121CS018 | D23: Harini P | E23: Male | F23: B.E. Computer Science and Engineering | G23: CSE | H23: 2026 | I23: Not Placed
A24: 19 | B24: 2025-26 | C24: 93621CS019 | D24: Ilakkiya R | E24: Female | F24: B.E. Computer Science and Engineering | G24: CSE | H24: 2026 | I24: Not Placed
A25: 20 | B25: 2025-26 | C25: 91321CS020 | D25: Yamini G | E25: Female | F25: B.E. Computer Science and Engineering | G25: CSE | H25: 2026 | I25: Qualified Competitive Exam
A26: 21 | B26: 2025-26 | C26: 95621CS021 | D26: Suresh G | E26: Female | F26: B.E. Computer Science and Engineering | G26: CSE | H26: 2026 | I26: Not Placed
A27: 22 | B27: 2025-26 | C27: 97921CS022 | D27: Prakash G | E27: Female | F27: B.E. Computer Science and Engineering | G27: CSE | H27: 2026 | I27: Qualified Competitive Exam
A28: 23 | B28: 2025-26 | C28: 96121CS023 | D28: Manoj K | E28: Male | F28: B.E. Computer Science and Engineering | G28: CSE | H28: 2026 | I28: Higher Studies
A29: 24 | B29: 2025-26 | C29: 94521CS024 | D29: Divya R | E29: Male | F29: B.E. Computer Science and Engineering | G29: CSE | H29: 2026 | I29: Placed | J29: Sify Technologies | K29: Chennai | L29: Design Engineer | M29: 4.81 | N29: 2026-04-26 | O29: Off-campus, verified | P29: DRV-2026-024 | R29: TPO Office | S29: 2026-07-04
A30: 25 | B30: 2025-26 | C30: 93521CS025 | D30: Prakash N | E30: Female | F30: B.E. Computer Science and Engineering | G30: CSE | H30: 2026 | I30: Placed | J30: L&T Construction | K30: Chennai | L30: Design Engineer | M30: 6.08 | N30: 2026-04-21 | O30: Off-campus, verified | P30: DRV-2026-006 | Q30: Open evidence | R30: TPO Office | S30: 2026-07-04
A31: 26 | B31: 2025-26 | C31: 97121CS026 | D31: Mohan K | E31: Female | F31: B.E. Computer Science and Engineering | G31: CSE | H31: 2026 | I31: Not Placed
A32: 27 | B32: 2025-26 | C32: 96021CS027 | D32: Harini S | E32: Male | F32: B.E. Computer Science and Engineering | G32: CSE | H32: 2026 | I32: Placed | J32: Sify Technologies | K32: Chennai | L32: Graduate Engineer Trainee | M32: 3.24 | N32: 2026-02-01 | O32: Campus drive via Velai Vaaippu | P32: DRV-2026-038 | Q32: Open evidence | R32: TPO Office | S32: 2026-07-26
A33: 28 | B33: 2025-26 | C33: 98621CS028 | D33: Yamini B | E33: Female | F33: B.E. Computer Science and Engineering | G33: CSE | H33: 2026 | I33: Not Placed
A34: 29 | B34: 2025-26 | C34: 98021CS029 | D34: Yamini G | E34: Male | F34: B.E. Computer Science and Engineering | G34: CSE | H34: 2026 | I34: Placed | J34: Sify Technologies | K34: Chennai | L34: Test Engineer | M34: 3.11 | N34: 2026-06-05 | O34: Pool campus drive | P34: DRV-2026-013 | Q34: Open evidence | R34: TPO Office | S34: 2026-07-07
A35: 30 | B35: 2025-26 | C35: 93721CS030 | D35: Divya P | E35: Male | F35: B.E. Computer Science and Engineering | G35: CSE | H35: 2026 | I35: Placed | J35: L&T Construction | K35: Chennai | L35: Systems Engineer | M35: 4.92 | N35: 2026-04-27 | O35: Campus drive via Velai Vaaippu | P35: DRV-2026-004 | Q35: Open evidence | R35: TPO Office | S35: 2026-07-12
A36: 31 | B36: 2025-26 | C36: 97621CS031 | D36: Swetha B | E36: Male | F36: B.E. Computer Science and Engineering | G36: CSE | H36: 2026 | I36: Placed | J36: Hexaware | K36: Chennai | L36: Graduate Engineer Trainee | M36: 4.25 | N36: 2026-01-28 | O36: Pool campus drive | P36: DRV-2026-012 | Q36: Open evidence | R36: TPO Office | S36: 2026-07-25
A37: 32 | B37: 2025-26 | C37: 92821CS032 | D37: Yamini M | E37: Male | F37: B.E. Computer Science and Engineering | G37: CSE | H37: 2026 | I37: Placed | J37: Hexaware | K37: Chennai | L37: Software Engineer | M37: 3.85 | N37: 2026-05-17 | O37: Pool campus drive | P37: DRV-2026-007 | Q37: Open evidence | R37: TPO Office | S37: 2026-07-02
A38: 33 | B38: 2025-26 | C38: 94521CS033 | D38: Revathi K | E38: Male | F38: B.E. Computer Science and Engineering | G38: CSE | H38: 2026 | I38: Placed | J38: Hexaware | K38: Chennai | L38: Associate Developer | M38: 4.32 | N38: 2026-01-15 | O38: Off-campus, verified | P38: DRV-2026-040 | Q38: Open evidence | R38: TPO Office | S38: 2026-07-20
A39: 34 | B39: 2025-26 | C39: 99821CS034 | D39: Dinesh K | E39: Female | F39: B.E. Computer Science and Engineering | G39: CSE | H39: 2026 | I39: Placed | J39: Hexaware | K39: Chennai | L39: Graduate Engineer Trainee | M39: 4.6 | N39: 2026-03-18 | O39: Campus drive via Velai Vaaippu | P39: DRV-2026-029 | Q39: Open evidence | R39: TPO Office | S39: 2026-07-04
A40: 35 | B40: 2025-26 | C40: 95021CS035 | D40: Nandhini N | E40: Male | F40: B.E. Computer Science and Engineering | G40: CSE | H40: 2026 | I40: Placed | J40: Tata Elxsi | K40: Chennai | L40: Software Engineer | M40: 5.33 | N40: 2026-03-26 | O40: Campus drive via Velai Vaaippu | P40: DRV-2026-010 | Q40: Open evidence | R40: TPO Office | S40: 2026-07-21
A41: 36 | B41: 2025-26 | C41: 94221CS036 | D41: Lavanya M | E41: Female | F41: B.E. Computer Science and Engineering | G41: CSE | H41: 2026 | I41: Not Placed
A42: 37 | B42: 2025-26 | C42: 96021CS037 | D42: Prakash S | E42: Male | F42: B.E. Computer Science and Engineering | G42: CSE | H42: 2026 | I42: Not Placed
...

Sheet Progression
A1: Higher Studies and Competitive Examinations
A2: Sample Engineering College · Academic year 2025-26
A5: Sl. No. | B5: Academic Year | C5: Register Number | D5: Name of the Student | E5: Programme Graduated From | F5: Department | G5: Progression Type | H5: Institution / Examination | I5: Programme Joined / Result | J5: Evidence on Record
A6: 1 | B6: 2025-26 | C6: 96021CS001 | D6: Gokul M | E6: B.E. Computer Science and Engineering | F6: CSE | G6: Higher Studies | H6: IIT Madras | I6: M.E. Computer Science | J6: Open evidence
A7: 2 | B7: 2025-26 | C7: 98321CS007 | D7: Naveen G | E7: B.E. Computer Science and Engineering | F7: CSE | G7: Qualified Competitive Exam | H7: TNPSC Group II | I7: Qualified | J7: Open evidence
A8: 3 | B8: 2025-26 | C8: 97021CS009 | D8: Priya P | E8: B.E. Computer Science and Engineering | F8: CSE | G8: Higher Studies | H8: Anna University, Chennai | I8: MBA | J8: Open evidence
A9: 4 | B9: 2025-26 | C9: 91321CS020 | D9: Yamini G | E9: B.E. Computer Science and Engineering | F9: CSE | G9: Qualified Competitive Exam | H9: GATE 2026 | I9: Qualified | J9: Open evidence
A10: 5 | B10: 2025-26 | C10: 97921CS022 | D10: Prakash G | E10: B.E. Computer Science and Engineering | F10: CSE | G10: Qualified Competitive Exam | H10: CAT 2025 | I10: Qualified | J10: Open evidence
A11: 6 | B11: 2025-26 | C11: 96121CS023 | D11: Manoj K | E11: B.E. Computer Science and Engineering | F11: CSE | G11: Higher Studies | H11: NIT Trichy | I11: M.E. Structural Engineering | J11: Open evidence
A12: 7 | B12: 2025-26 | C12: 91221IT008 | D12: Karthik R | E12: B.Tech Information Technology | F12: IT | G12: Higher Studies | H12: IIT Madras | I12: M.E. Power Systems | J12: Open evidence
A13: 8 | B13: 2025-26 | C13: 97421IT012 | D13: Priya T | E13: B.Tech Information Technology | F13: IT | G13: Higher Studies | H13: IIT Madras | I13: M.Tech VLSI | J13: Open evidence
A14: 9 | B14: 2025-26 | C14: 95921IT016 | D14: Yamini B | E14: B.Tech Information Technology | F14: IT | G14: Qualified Competitive Exam | H14: CAT 2025 | I14: Qualified | J14: Open evidence
A15: 10 | B15: 2025-26 | C15: 97721IT018 | D15: Dinesh M | E15: B.Tech Information Technology | F15: IT | G15: Qualified Competitive Exam | H15: UPSC ESE 2026 | I15: Qualified | J15: Open evidence
A16: 11 | B16: 2025-26 | C16: 98821EC004 | D16: Pavithra N | E16: B.E. Electronics and Communication Engineering | F16: ECE | G16: Qualified Competitive Exam | H16: GRE | I16: Qualified
A17: 12 | B17: 2025-26 | C17: 99521EC021 | D17: Karthik P | E17: B.E. Electronics and Communication Engineering | F17: ECE | G17: Higher Studies | H17: VIT Vellore | I17: M.E. Power Systems | J17: Open evidence
A18: 13 | B18: 2025-26 | C18: 95921EC026 | D18: Vijay N | E18: B.E. Electronics and Communication Engineering | F18: ECE | G18: Qualified Competitive Exam | H18: GRE | I18: Qualified | J18: Open evidence
A19: 14 | B19: 2025-26 | C19: 94221EE001 | D19: Thanya V | E19: B.E. Electrical and Electronics Engineering | F19: EEE | G19: Higher Studies | H19: PSG College of Technology | I19: M.Tech VLSI | J19: Open evidence
A20: 15 | B20: 2025-26 | C20: 96021EE009 | D20: Lavanya K | E20: B.E. Electrical and Electronics Engineering | F20: EEE | G20: Higher Studies | H20: Anna University, Chennai | I20: M.E. Power Systems | J20: Open evidence
A21: 16 | B21: 2025-26 | C21: 99721EE020 | D21: Vimal M | E21: B.E. Electrical and Electronics Engineering | F21: EEE | G21: Qualified Competitive Exam | H21: GATE 2026 | I21: Qualified | J21: Open evidence
A22: 17 | B22: 2025-26 | C22: 91021ME003 | D22: Sandhya V | E22: B.E. Mechanical Engineering | F22: MECH | G22: Qualified Competitive Exam | H22: CAT 2025 | I22: Qualified | J22: Open evidence
A23: 18 | B23: 2025-26 | C23: 94121ME006 | D23: Vignesh R | E23: B.E. Mechanical Engineering | F23: MECH | G23: Higher Studies | H23: Anna University, Chennai | I23: M.E. Computer Science | J23: Open evidence
A24: 19 | B24: 2025-26 | C24: 98621ME008 | D24: Muthu V | E24: B.E. Mechanical Engineering | F24: MECH | G24: Higher Studies | H24: IIT Madras | I24: M.E. Structural Engineering | J24: Open evidence
A25: 20 | B25: 2025-26 | C25: 94421ME012 | D25: Suresh R | E25: B.E. Mechanical Engineering | F25: MECH | G25: Higher Studies | H25: IIT Madras | I25: MBA | J25: Open evidence

Sheet Employer Summary
A1: Recruiting Employers
A2: Sample Engineering College · Academic year 2025-26
A5: Employer | B5: Offers Made | C5: Departments Recruited From | D5: Average Package (Rs. LPA) | E5: Highest Package (Rs. LPA) | F5: Source of Offers
A6: Ashok Leyland | B6: 4 | C6: CSE, IT, ECE | D6: 5.15 | E6: 5.41 | F6: Campus drive via Velai Vaaippu, Off-campus, verified, Pool campus drive
A7: Cognizant | B7: 8 | C7: IT, ECE, EEE, MECH | D7: 4.88625 | E7: 5.36 | F7: Pool campus drive, Off-campus, verified, Campus drive via Velai Vaaippu
A8: Freshworks | B8: 13 | C8: CSE, IT, ECE, EEE, MECH | D8: 7.2161538 | E8: 8.22 | F8: Campus drive via Velai Vaaippu, Off-campus, verified, Pool campus drive
A9: HCLTech | B9: 7 | C9: CSE, IT, ECE, EEE, MECH | D9: 4.3885714 | E9: 5.18 | F9: Pool campus drive, Campus drive via Velai Vaaippu, Off-campus, verified
A10: Hexaware | B10: 7 | C10: CSE, ECE, EEE | D10: 4.4171429 | E10: 5.14 | F10: Campus drive via Velai Vaaippu, Pool campus drive, Off-campus, verified
A11: Infosys | B11: 7 | C11: CSE, IT, ECE, EEE, MECH | D11: 4.8414286 | E11: 5.59 | F11: Pool campus drive, Off-campus, verified, Campus drive via Velai Vaaippu
A12: L&T Construction | B12: 6 | C12: CSE, ECE, MECH | D12: 5.0816667 | E12: 6.08 | F12: Off-campus, verified, Campus drive via Velai Vaaippu, Pool campus drive
A13: Sify Technologies | B13: 6 | C13: CSE, IT | D13: 3.8583333 | E13: 4.81 | F13: Campus drive via Velai Vaaippu, Off-campus, verified, Pool campus drive
A14: TCS | B14: 11 | C14: CSE, IT, ECE, EEE, MECH | D14: 4.2054545 | E14: 4.99 | F14: Pool campus drive, Campus drive via Velai Vaaippu, Off-campus, verified
A15: Tata Elxsi | B15: 15 | C15: CSE, IT, ECE, EEE, MECH | D15: 5.8373333 | E15: 6.86 | F15: Campus drive via Velai Vaaippu, Off-campus, verified
A16: Wipro | B16: 5 | C16: CSE, ECE, EEE | D16: 3.74 | E16: 4.66 | F16: Off-campus, verified, Pool campus drive, Campus drive via Velai Vaaippu
A17: Zoho Corporation | B17: 5 | C17: IT, ECE, EEE | D17: 6.456 | E17: 6.72 | F17: Campus drive via Velai Vaaippu, Off-campus, verified

Sheet DVV Evidence Log
A1: Evidence Log
A2: Sample Engineering College · Academic year 2025-26 · Work the missing list to zero
A5: Register Number | B5: Name | C5: Department | D5: Claim Made | E5: Evidence on Record | F5: Status
A6: 93721CS002 | B6: Meena G | C6: CSE | D6: Placed — Tata Elxsi | E6: OFFER-93721CS002.pdf | F6: Complete
A7: 98321CS003 | B7: Sandhya R | C7: CSE | D7: Placed — HCLTech | E7: OFFER-98321CS003.pdf | F7: Complete
A8: 99721CS004 | B8: Anitha G | C8: CSE | D8: Placed — Ashok Leyland | E8: OFFER-99721CS004.pdf | F8: Complete
A9: 95021CS005 | B9: Kalaiselvi T | C9: CSE | D9: Placed — Ashok Leyland | E9: OFFER-95021CS005.pdf | F9: Complete
A10: 96721CS006 | B10: Abinaya V | C10: CSE | D10: Placed — TCS | E10: NOT ON FILE | F10: MISSING
A11: 95521CS011 | B11: Divya N | C11: CSE | D11: Placed — Freshworks | E11: OFFER-95521CS011.pdf | F11: Complete
A12: 93121CS012 | B12: Abinaya S | C12: CSE | D12: Placed — Infosys | E12: OFFER-93121CS012.pdf | F12: Complete
A13: 92021CS013 | B13: Prakash M | C13: CSE | D13: Placed — Wipro | E13: NOT ON FILE | F13: MISSING
A14: 98821CS014 | B14: Kalaiselvi V | C14: CSE | D14: Placed — Sify Technologies | E14: OFFER-98821CS014.pdf | F14: Complete
A15: 96021CS015 | B15: Muthu T | C15: CSE | D15: Placed — Freshworks | E15: OFFER-96021CS015.pdf | F15: Complete
A16: 92321CS016 | B16: Sriram R | C16: CSE | D16: Placed — Hexaware | E16: OFFER-92321CS016.pdf | F16: Complete
... A119: 94421ME012 | B119: Suresh R | C119: MECH | D119: Higher Studies | E119: ADM-94421ME012.pdf | F119: Complete
